2016/09/22 15:29:58 2016/09/21 09:53:38 http: panic serving [::1]:56452: runtime error: index out of range
goroutine 18 [running]:
net/http.(*conn).serve.func1(0xc42012e080)
	/usr/local/Cellar/go/1.7.1/libexec/src/net/http/server.go:1491 +0x12a
panic(0x2fbca0, 0xc42000c0e0)
	/usr/local/Cellar/go/1.7.1/libexec/src/runtime/panic.go:458 +0x243

2016/09/22 15:38:32 Log Entry # 1 
 2016/09/21 09:53:38 http: panic serving [::1]:56452: runtime error: index out of range
goroutine 18 [running]:
net/http.(*conn).serve.func1(0xc42012e080)
	/usr/local/Cellar/go/1.7.1/libexec/src/net/http/server.go:1491 +0x12a
panic(0x2fbca0, 0xc42000c0e0)
	/usr/local/Cellar/go/1.7.1/libexec/src/runtime/panic.go:458 +0x243

2016/09/22 15:38:45 Log Entry # 2 
 Traceback (most recent call last):
  File "tb.py", line 15, in <module>
    a()
  File "tb.py", line 3, in a
    j=b(i)
  File "tb.py", line 9, in b
    c()
  File "tb.py", line 13, in c
    error()
NameError: global name 'error' is not defined

