Traceback (most recent call last):
  File "tb.py", line 15, in <module>
    a()
  File "tb.py", line 3, in a
    j=b(i)
  File "tb.py", line 9, in b
    c()
  File "tb.py", line 13, in c
    error()
NameError: global name 'error' is not defined
